import React from "react";
import { ErrorBoundary as ReactErrorBoundary } from "react-error-boundary";
import { AlertTriangle, RefreshCw } from "lucide-react";

const isDevelopment = import.meta.env.MODE === "development";

interface ErrorFallbackProps {
  error: Error;
  resetErrorBoundary: () => void;
}

const ErrorFallback: React.FC<ErrorFallbackProps> = ({
  error,
  resetErrorBoundary,
}) => {
  return (
    <div className="min-h-screen flex items-center justify-center bg-gray-50">
      <div className="max-w-md w-full bg-white rounded-lg shadow-lg p-6 text-center">
        <div className="mx-auto flex items-center justify-center h-12 w-12 rounded-full bg-red-100 mb-4">
          <AlertTriangle className="h-6 w-6 text-red-600" />
        </div>

        <h2 className="text-lg font-semibold text-gray-900 mb-2">
          Algo sali√≥ mal
        </h2>

        <p className="text-sm text-gray-600 mb-4">
          Ha ocurrido un error inesperado. Por favor, intenta de nuevo.
        </p>

        {isDevelopment && (
          <details className="mb-4 text-left">
            <summary className="cursor-pointer text-sm text-gray-500 hover:text-gray-700">
              Detalles del error
            </summary>
            <pre className="mt-2 text-xs text-red-600 bg-red-50 p-2 rounded overflow-auto">
              {error.message}
              {error.stack && `\n\n${error.stack}`}
            </pre>
          </details>
        )}

        <button
          onClick={resetErrorBoundary}
          className="inline-flex items-center px-4 py-2 border border-transparent text-sm font-medium rounded-md text-white bg-blue-600 hover:bg-blue-700 focus:outline-none focus:ring-2 focus:ring-offset-2 focus:ring-blue-500"
        >
          <RefreshCw className="h-4 w-4 mr-2" />
          Intentar de nuevo
        </button>
      </div>
    </div>
  );
};

interface ErrorBoundaryProps {
  children: React.ReactNode;
  fallback?: React.ComponentType<ErrorFallbackProps>;
}

export const ErrorBoundary: React.FC<ErrorBoundaryProps> = ({
  children,
  fallback = ErrorFallback,
}) => {
  const handleError = (error: Error, errorInfo: React.ErrorInfo) => {
    // Log error to console in development
    if (isDevelopment) {
      console.error("Error caught by boundary:", error, errorInfo);
    }

    // Here you could send error to your error reporting service
    // Example: Sentry.captureException(error, { extra: errorInfo });
  };

  return (
    <ReactErrorBoundary
      FallbackComponent={fallback}
      onError={handleError}
      onReset={() => {
        // Reset the state of your app here
        window.location.reload();
      }}
    >
      {children}
    </ReactErrorBoundary>
  );
};
